Workbook

Sheet 📊 Dashboard
A1: HATE CRIME SUPPORT PROJECT | WEST LONDON EQUALITY CENTRE | City Bridge Foundation
A2: Nov 2025 – Oct 2030 | £480,801 | 5-Year Monitoring Dashboard | All figures update automatically from data sheets
A4: ⚡ FUNDER QUICK-ANSWER PANEL — Instant answers to common funder questions
A5: Total Clients to Date | F5: % from Ealing | K5: Active Cases | P5: % Under 25 | U5: % of 5-Year Target Met
A6: =COUNTA('📋 Client Intake'!C5:C1004) -> 6 | F6: =IFERROR(COUNTIF('📋 Client Intake'!G5:G1004,"Ealing")/COUNTA('📋 Client Intake'!C5:C1004),0) -> 0.5 | K6: =COUNTIF('📋 Client Intake'!F5:F1004,"Active") -> 5 | P6: =IFERROR(COUNTIF('📋 Client Intake'!I5:I1004,"Under 25")/COUNTA('📋 Client Intake'!C5:C1004),0) -> 0 | U6: =IFERROR(COUNTA('📋 Client Intake'!C5:C1004)/750,0) -> 0.008
A8: % from Hillingdon | F8: % from Hounslow | K8: % Female | P8: High Risk Cases | U8: Referrals This Quarter
A9: =IFERROR(COUNTIF('📋 Client Intake'!G5:G1004,"Hillingdon")/COUNTA('📋 Client Intake'!C5:C1004),0) -> 0.33333333 | F9: =IFERROR(COUNTIF('📋 Client Intake'!G5:G1004,"Hounslow")/COUNTA('📋 Client Intake'!C5:C1004),0) -> 0.16666667 | K9: =IFERROR(COUNTIF('📋 Client Intake'!J5:J1004,"Female")/COUNTA('📋 Client Intake'!C5:C1004),0) -> 0.5 | P9: =COUNTIF('📋 Client Intake'!M5:M1004,"High") -> 3 | U9: =IFERROR(COUNTIFS('📋 Client Intake'!E5:E1004,">="&'⚙ Settings'!C20,'📋 Client Intake'!E5:E1004,"<="&'⚙ Settings'!C21),0) -> 1
A12: 5-YEAR PROGRESS TRACKER — Cases handled vs target per year
A13: Year 1 (2025-26) | E13: Year 2 (2026-27) | I13: Year 3 (2027-28) | M13: Year 4 (2028-29) | Q13: Year 5 (2029-30) | U13: Total (5 Years)
A14: Target: 50 | E14: Target: 100 | I14: Target: 150 | M14: Target: 200 | Q14: Target: 250 | U14: Target: 750
A15: =COUNTIFS('📋 Client Intake'!AB5:AB1004,"Year 1") -> 4 | E15: =COUNTIFS('📋 Client Intake'!AB5:AB1004,"Year 2") -> 2 | I15: =COUNTIFS('📋 Client Intake'!AB5:AB1004,"Year 3") -> 0 | M15: =COUNTIFS('📋 Client Intake'!AB5:AB1004,"Year 4") -> 0 | Q15: =COUNTIFS('📋 Client Intake'!AB5:AB1004,"Year 5") -> 0 | U15: =COUNTA('📋 Client Intake'!C5:C1004) -> 6
A17: =IFERROR(A15/50,0) -> 0.08 | E17: =IFERROR(E15/100,0) -> 0.02 | I17: =IFERROR(I15/150,0) -> 0 | M17: =IFERROR(M15/200,0) -> 0 | Q17: =IFERROR(Q15/250,0) -> 0 | U17: =IFERROR(U15/750,0) -> 0.008
A18: Note: Targets shown above are CUMULATIVE 5-year totals. Annual target: 50 cases per year.
A19: OUTCOME PERFORMANCE TRACKER — 5 Key Outcomes | Updates live from Outcome Tracker
A20: Outcome | I20: 5-Yr Target | L20: Yr 1 | O20: Yr 2 | R20: Yr 3 | U20: Yr 4 | X20: Yr 5 | Z20: % Met
A21: Improved access to legal advice & casework support | I21: 80% reporting better access | L21: =COUNTIFS('📊 Outcome Tracker'!E5:E1004,"Yes",'📊 Outcome Tracker'!H5:H1004,"Year 1") -> 0 | O21: =COUNTIFS('📊 Outcome Tracker'!E5:E1004,"Yes",'📊 Outcome Tracker'!H5:H1004,"Year 2") -> 0 | R21: =COUNTIFS('📊 Outcome Tracker'!E5:E1004,"Yes",'📊 Outcome Tracker'!H5:H1004,"Year 3") -> 0 | U21: =COUNTIFS('📊 Outcome Tracker'!E5:E1004,"Yes",'📊 Outcome Tracker'!H5:H1004,"Year 4") -> 0 | X21: =COUNTIFS('📊 Outcome Tracker'!E5:E1004,"Yes",'📊 Outcome Tracker'!H5:H1004,"Year 5") -> 0 | Z21: =IFERROR(COUNTIF('📊 Outcome Tracker'!E5:E1004,"Yes")/80,0) -> 0.0625
A22: Empowered victims — confidence to report hate crime | I22: 60% increase in reporting | L22: =COUNTIFS('📊 Outcome Tracker'!F5:F1004,"Yes",'📊 Outcome Tracker'!H5:H1004,"Year 1") -> 0 | O22: =COUNTIFS('📊 Outcome Tracker'!F5:F1004,"Yes",'📊 Outcome Tracker'!H5:H1004,"Year 2") -> 0 | R22: =COUNTIFS('📊 Outcome Tracker'!F5:F1004,"Yes",'📊 Outcome Tracker'!H5:H1004,"Year 3") -> 0 | U22: =COUNTIFS('📊 Outcome Tracker'!F5:F1004,"Yes",'📊 Outcome Tracker'!H5:H1004,"Year 4") -> 0 | X22: =COUNTIFS('📊 Outcome Tracker'!F5:F1004,"Yes",'📊 Outcome Tracker'!H5:H1004,"Year 5") -> 0 | Z22: =IFERROR(COUNTIF('📊 Outcome Tracker'!F5:F1004,"Yes")/60,0) -> 0.05
A23: Strengthened collaboration among stakeholders | I23: 20 formal partnerships | L23: =COUNTIFS('📊 Outcome Tracker'!G5:G1004,"Yes",'📊 Outcome Tracker'!H5:H1004,"Year 1") -> 0 | O23: =COUNTIFS('📊 Outcome Tracker'!G5:G1004,"Yes",'📊 Outcome Tracker'!H5:H1004,"Year 2") -> 0 | R23: =COUNTIFS('📊 Outcome Tracker'!G5:G1004,"Yes",'📊 Outcome Tracker'!H5:H1004,"Year 3") -> 0 | U23: =COUNTIFS('📊 Outcome Tracker'!G5:G1004,"Yes",'📊 Outcome Tracker'!H5:H1004,"Year 4") -> 0 | X23: =COUNTIFS('📊 Outcome Tracker'!G5:G1004,"Yes",'📊 Outcome Tracker'!H5:H1004,"Year 5") -> 0 | Z23: =IFERROR(COUNTIF('📊 Outcome Tracker'!G5:G1004,"Yes")/20,0) -> 0.05
A24: Increased awareness of HC reporting & prevention | I24: 85% report increased knowledge | L24: =COUNTIFS('📊 Outcome Tracker'!H5:H1004,"Yes",'📊 Outcome Tracker'!H5:H1004,"Year 1") -> 0 | O24: =COUNTIFS('📊 Outcome Tracker'!H5:H1004,"Yes",'📊 Outcome Tracker'!H5:H1004,"Year 2") -> 0 | R24: =COUNTIFS('📊 Outcome Tracker'!H5:H1004,"Yes",'📊 Outcome Tracker'!H5:H1004,"Year 3") -> 0 | U24: =COUNTIFS('📊 Outcome Tracker'!H5:H1004,"Yes",'📊 Outcome Tracker'!H5:H1004,"Year 4") -> 0 | X24: =COUNTIFS('📊 Outcome Tracker'!H5:H1004,"Yes",'📊 Outcome Tracker'!H5:H1004,"Year 5") -> 0 | Z24: =IFERROR(COUNTIF('📊 Outcome Tracker'!H5:H1004,"Yes")/85,0) -> 0.070588235
A25: Sustainable community-led solutions | I25: 10 grassroots-led initiatives | L25: =COUNTIFS('📊 Outcome Tracker'!I5:I1004,"Yes",'📊 Outcome Tracker'!H5:H1004,"Year 1") -> 0 | O25: =COUNTIFS('📊 Outcome Tracker'!I5:I1004,"Yes",'📊 Outcome Tracker'!H5:H1004,"Year 2") -> 0 | R25: =COUNTIFS('📊 Outcome Tracker'!I5:I1004,"Yes",'📊 Outcome Tracker'!H5:H1004,"Year 3") -> 0 | U25: =COUNTIFS('📊 Outcome Tracker'!I5:I1004,"Yes",'📊 Outcome Tracker'!H5:H1004,"Year 4") -> 0 | X25: =COUNTIFS('📊 Outcome Tracker'!I5:I1004,"Yes",'📊 Outcome Tracker'!H5:H1004,"Year 5") -> 0 | Z25: =IFERROR(COUNTIF('📊 Outcome Tracker'!I5:I1004,"Yes")/10,0) -> 0
A27: LIVE CLIENT BREAKDOWN — Auto-calculated from Client Intake
A28: CLIENTS BY BOROUGH | K28: BY AGE GROUP | T28: BY GENDER
A29: Ealing | D29: Hillingdon | G29: Hounslow | K29: Under 25 | N29: 25-49 | Q29: 50+ | T29: Female | W29: Male | Y29: Non-binary/Other
A30: =COUNTIF('📋 Client Intake'!G5:G1004,"Ealing") -> 3 | D30: =COUNTIF('📋 Client Intake'!G5:G1004,"Hillingdon") -> 2 | G30: =COUNTIF('📋 Client Intake'!G5:G1004,"Hounslow") -> 1 | K30: =COUNTIF('📋 Client Intake'!I5:I1004,"Under 25") -> 0 | N30: =COUNTIF('📋 Client Intake'!I5:I1004,"25-49") -> 0 | Q30: =COUNTIF('📋 Client Intake'!I5:I1004,"50-64")+COUNTIF('📋 Client Intake'!I5:I1004,"65+") -> 0 | T30: =COUNTIF('📋 Client Intake'!J5:J1004,"Female") -> 3 | W30: =COUNTIF('📋 Client Intake'!J5:J1004,"Male") -> 2 | Y30: =COUNTIF('📋 Client Intake'!J5:J1004,"Non-binary/Other") -> 0
A33: RISK LEVELS — Live from Client Intake
A34: High Risk | I34: Medium Risk | R34: Low Risk
A35: =COUNTIF('📋 Client Intake'!M5:M1004,"High") -> 3 | I35: =COUNTIF('📋 Client Intake'!M5:M1004,"Medium") -> 2 | R35: =COUNTIF('📋 Client Intake'!M5:M1004,"Low") -> 1
A38: QUARTERLY SNAPSHOT — Set dates in ⚙ Settings tab
A39: Clients This Quarter | G39: Activities This Quarter | M39: Cases Closed This Quarter | S39: New Referrals This Quarter
A40: =IFERROR(COUNTIFS('📋 Client Intake'!E5:E1004,">="&'⚙ Settings'!C20,'📋 Client Intake'!E5:E1004,"<="&'⚙ Settings'!C21),0) -> 1 | G40: =IFERROR(COUNTIFS('📅 Activities'!A19:A1000,">="&'⚙ Settings'!C20,'📅 Activities'!A19:A1000,"<="&'⚙ Settings'!C21),0) -> 0 | M40: =IFERROR(COUNTIFS('📋 Client Intake'!F5:F1004,"Closed",'📋 Client Intake'!E5:E1004,">="&'⚙ Settings'!C20),0) -> 0 | S40: =IFERROR(COUNTIFS('📋 Client Intake'!E5:E1004,">="&'⚙ Settings'!C20,'📋 Client Intake'!E5:E1004,"<="&'⚙ Settings'!C21),0) -> 1
A43: VOLUNTEERS & TRAINING — Live from Volunteer Log
A44: Active Volunteers | G44: Total Hours Volunteered | M44: Fully Trained Volunteers | S44: Training Sessions Delivered
A45: =COUNTIF('🙋 Volunteer Log'!G12:G211,"Active") -> 4 | G45: =SUM('🙋 Volunteer Log'!J12:J211) -> 54 | M45: =COUNTIF('🙋 Volunteer Log'!F12:F211,"Complete") -> 0 | S45: =COUNTA('🎓 Training Register'!B11:B500) -> 4

Sheet 📋 Client Intake
A1: CLIENT INTAKE FORM | Hate Crime Support Project | WLEC
A2: Record full client profile at START of journey. One row per client. Use 📊 Outcome Tracker to log progress at any point during the project.
A3: ℹ️ All dropdown fields are required for dashboard reporting. Client Ref auto-generates as HC/1, HC/2 etc. Full Name column is for internal use only — treat as confidential. | O3: NATURE OF INCIDENT — tick all that apply
A4: Client Ref (Auto) | B4: Full Name | C4: Initials / Anonymised ID | D4: Caseworker / Support Worker | E4: Date Referred | F4: Case Status | G4: Borough | H4: Referral Source | I4: Age Group | J4: Gender Identity | K4: Ethnic Origin | L4: Religion | M4: Risk Level | N4: Type of Hate Crime | O4: Harassment /ASB | P4: Verbal Abuse | Q4: Physical Assault | R4: Criminal Damage | S4: Online Abuse | T4: Stalking | U4: Hate Incident | V4: Other Incident | W4: Reported to Police? | X4: First Language | Y4: Sexual Orientation | Z4: Disability / Medical Condition | AA4: Housing Situation | AB4: Project Year | AC4: Presenting Issue (Brief Description)
A5: =IF(C5<>"","HC/"&(ROW()-4),"") -> HC/1 | B5: Freda Ritchie 1 | C5: FR1 | D5: Omer Ul-haque | E5: 46168 | F5: Active | G5: Ealing | H5: Other | I5: 26-55 | J5: Female | K5: White: British | L5: Prefer not to say | M5: High | N5: Homophobic | O5: ✓ | W5: Yes – no action taken | X5: English | Y5: Do not wish to state | Z5: Mental Health | AA5: Other | AB5: Year 1 | AC5: Homophobia, within shared accomodation, issues with other tenant.
A6: =IF(C6<>"","HC/"&(ROW()-4),"") -> HC/2 | B6: Freda Ritchie 2 | C6: FR2 | D6: Paula Howell | E6: 46001 | F6: Active | G6: Hillingdon | H6: Self-Referral | I6: 18-25 | J6: Male | K6: Black: Caribbean | L6: Christian | M6: Medium | N6: Racial | O6: ✓ | P6: ✓ | W6: No | X6: English | Y6: Straight | Z6: None | AA6: Social housing | AB6: Year 1 | AC6: Racial abuse from neighbour, ongoing over 6 months.
A7: =IF(C7<>"","HC/"&(ROW()-4),"") -> HC/3 | B7: Freda Ritchie 3 | C7: FR3 | D7: Reena Malhan | E7: 46037 | F7: Active | G7: Ealing | H7: MPS (Police) | I7: 26-55 | J7: Female | K7: Asian: Pakistani | L7: Muslim | M7: High | N7: Religious | O7: ✓ | S7: ✓ | W7: Yes | X7: Other | Y7: Prefer not to say | Z7: None | AA7: Owner occupier | AB7: Year 1 | AC7: Religiously motivated harassment at workplace.
A8: =IF(C8<>"","HC/"&(ROW()-4),"") -> HC/4 | B8: Freda Ritchie 4 | C8: FR4 | D8: Omer Ul-haque | E8: 46073 | F8: Closed | G8: Hounslow | H8: Citizens Advice | I8: 55-65 | J8: Male | K8: White: Irish | L8: No religion | M8: Low | N8: Disability | O8: ✓ | W8: Yes – no action taken | X8: English | Y8: Straight | Z8: Mobility | AA8: Owner occupier | AB8: Year 1 | AC8: Disability hate crime — verbal abuse on public transport.
A9: =IF(C9<>"","HC/"&(ROW()-4),"") -> HC/5 | B9: Freda Ritchie 5 | C9: FR5 | D9: Paula Howell | E9: 46331 | F9: Active | G9: Ealing | H9: Victim Support | I9: Under 18 | J9: Non-binary | K9: Mixed: White/Asian | L9: Buddhist | M9: High | N9: Homophobic | O9: ✓ | P9: ✓ | T9: ✓ | W9: No | X9: English | Y9: Not Sure | Z9: Mental Health | AA9: Social housing | AB9: Year 2 | AC9: Homophobic bullying at school, online threats via social media.
A10: =IF(C10<>"","HC/"&(ROW()-4),"") -> HC/6 | B10: Freda Ritchie 6 | C10: FR6 | D10: Reena Malhan | E10: 46359 | F10: Active | G10: Hillingdon | H10: Hillingdon Refugee Support Organisation | I10: 26-55 | J10: Female | K10: Middle Eastern | L10: Muslim | M10: Medium | N10: Racial | O10: ✓ | P10: ✓ | W10: Unknown | X10: Other | Y10: Do not wish to state | Z10: None | AA10: Temporary/hostel | AB10: Year 2 | AC10: Racial and religious hate crime, client is asylum seeker.
A11: =IF(C11<>"","HC/"&(ROW()-4),"")
A12: =IF(C12<>"","HC/"&(ROW()-4),"")
A13: =IF(C13<>"","HC/"&(ROW()-4),"")
A14: =IF(C14<>"","HC/"&(ROW()-4),"")
A15: =IF(C15<>"","HC/"&(ROW()-4),"")
A16: =IF(C16<>"","HC/"&(ROW()-4),"")
A17: =IF(C17<>"","HC/"&(ROW()-4),"")
A18: =IF(C18<>"","HC/"&(ROW()-4),"")
A19: =IF(C19<>"","HC/"&(ROW()-4),"")
A20: =IF(C20<>"","HC/"&(ROW()-4),"")
A21: =IF(C21<>"","HC/"&(ROW()-4),"")
A22: =IF(C22<>"","HC/"&(ROW()-4),"")
... A1004: =IF(C1004<>"","HC/"&(ROW()-4),"")

Sheet 📊 Outcome Tracker
A1: OUTCOME TRACKER | Hate Crime Support Project | WLEC
A2: Add a row each time you assess a client — at Intake, 3 months, 6 months, case closure, or any funder review. Multiple rows per client = full progress picture.
A3: ℹ️ Use same Client Ref as Client Intake. Column Q auto-scores 'Yes' responses. Dashboard counts feed from this sheet. | Greyed columns (K, L, M, O) are optional — complete when available. Core outcomes are columns E–I.
A4: Client Ref | B4: Assessment Date | C4: Assessment Stage | D4: Caseworker | E4: O1: Better Access to Legal Support (Y/N) | F4: O2: Increased Confidence to Report (Y/N) | G4: O3: Strengthened Partnership Engaged (Y/N) | H4: O4: Increased Awareness of HC (Y/N) | I4: O5: Community-Led Solution Initiated (Y/N) | J4: Project Year | K4: Satisfaction Rating (1-5) (Optional) | L4: Knowledge Score (pre) (Optional) | M4: Knowledge Score (post) (Optional) | N4: Reported to Police? (Y/N) | O4: Referred to Partner Org? (Optional) | P4: Outcome Score (Auto) | Q4: Notes / Evidence
A5: HC/1 | B5: 46168 | C5: Intake | D5: Omer Ul-haque | E5: No | F5: No | G5: No | H5: Yes | I5: No | J5: Year 1 | N5: Yes | O5: No | P5: =IF(A5="","",COUNTIF(E5:I5,"Yes")) -> 1 | Q5: Client newly referred — initial legal advice provided. Confidence low.
A6: HC/2 | B6: 46001 | C6: Intake | D6: Paula Howell | E6: No | F6: No | G6: No | H6: No | I6: No | J6: Year 1 | N6: No | O6: No | P6: =IF(A6="","",COUNTIF(E6:I6,"Yes")) -> 0 | Q6: Client referred self following racial abuse. Very distressed at intake.
A7: HC/3 | B7: 46037 | C7: Intake | D7: Reena Malhan | E7: No | F7: No | G7: No | H7: No | I7: No | J7: Year 1 | N7: Yes | O7: No | P7: =IF(A7="","",COUNTIF(E7:I7,"Yes")) -> 0 | Q7: High risk case — religious hate crime at workplace. Referred to legal team.
A8: HC/4 | B8: 46073 | C8: Intake | D8: Omer Ul-haque | E8: Yes | F8: No | G8: No | H8: Yes | I8: No | J8: Year 1 | N8: Yes | O8: No | P8: =IF(A8="","",COUNTIF(E8:I8,"Yes")) -> 2 | Q8: Client aware of legal rights. Case closed after resolution with transport authority.
A9: HC/2 | B9: 46091 | C9: 3 Month Review | D9: Paula Howell | E9: Yes | F9: No | G9: No | H9: Yes | I9: No | J9: Year 1 | K9: 3 | N9: No | O9: Yes | P9: =IF(A9="","",COUNTIF(E9:I9,"Yes")) -> 2 | Q9: Client engaged with community awareness session. Referred to Victim Support.
A10: HC/1 | B10: 46260 | C10: 3 Month Review | D10: Omer Ul-haque | E10: Yes | F10: Yes | G10: No | H10: Yes | I10: No | J10: Year 1 | K10: 4 | N10: Yes | O10: No | P10: =IF(A10="","",COUNTIF(E10:I10,"Yes")) -> 3 | Q10: Significant improvement in confidence. Legal case progressing.
A11: HC/3 | B11: 46218 | C11: 6 Month Review | D11: Reena Malhan | E11: Yes | F11: Yes | G11: Yes | H11: Yes | I11: No | J11: Year 1 | K11: 4 | L11: 2 | M11: 4 | N11: Yes | O11: Yes | P11: =IF(A11="","",COUNTIF(E11:I11,"Yes")) -> 4 | Q11: Strong progress — employer mediation successful. Referred to partnership org.
A12: HC/4 | B12: 46162 | C12: Case Closure | D12: Omer Ul-haque | E12: Yes | F12: Yes | G12: No | H12: Yes | I12: No | J12: Year 1 | K12: 5 | N12: Yes | O12: No | P12: =IF(A12="","",COUNTIF(E12:I12,"Yes")) -> 3 | Q12: Case closed positively. Client satisfied with outcome. Transport authority issued apology.
A13: HC/5 | B13: 46331 | C13: Intake | D13: Paula Howell | E13: No | F13: No | G13: No | H13: No | I13: No | J13: Year 2 | N13: No | O13: No | P13: =IF(A13="","",COUNTIF(E13:I13,"Yes")) -> 0 | Q13: Young non-binary client — homophobic bullying and online threats. High priority.
A14: HC/6 | B14: 46359 | C14: Intake | D14: Reena Malhan | E14: No | F14: No | G14: No | H14: No | I14: No | J14: Year 2 | N14: No | O14: No | P14: =IF(A14="","",COUNTIF(E14:I14,"Yes")) -> 0 | Q14: Asylum seeker — language barrier. Interpreter arranged. Complex case.
P15: =IF(A15="","",COUNTIF(E15:I15,"Yes"))
P16: =IF(A16="","",COUNTIF(E16:I16,"Yes"))
P17: =IF(A17="","",COUNTIF(E17:I17,"Yes"))
P18: =IF(A18="","",COUNTIF(E18:I18,"Yes"))
P19: =IF(A19="","",COUNTIF(E19:I19,"Yes"))
P20: =IF(A20="","",COUNTIF(E20:I20,"Yes"))
P21: =IF(A21="","",COUNTIF(E21:I21,"Yes"))
P22: =IF(A22="","",COUNTIF(E22:I22,"Yes"))
P23: =IF(A23="","",COUNTIF(E23:I23,"Yes"))
P24: =IF(A24="","",COUNTIF(E24:I24,"Yes"))
P25: =IF(A25="","",COUNTIF(E25:I25,"Yes"))
P26: =IF(A26="","",COUNTIF(E26:I26,"Yes"))
... P1004: =IF(A1004="","",COUNTIF(E1004:I1004,"Yes"))
A1006: OUTCOME ACHIEVEMENT SUMMARY — Auto-calculated
A1007: Outcome | E1007: Yes | F1007: Partial | G1007: No | H1007: N/A | I1007: Achievement %
A1008: O1 – Better access to legal advice & casework | E1008: =COUNTIF(E5:E1004,"Yes") -> 5 | F1008: =COUNTIF(E5:E1004,"Partial") -> 0 | G1008: =COUNTIF(E5:E1004,"No") -> 5 | H1008: =COUNTIF(E5:E1004,"N/A") -> 0 | I1008: =IFERROR(E1008/(E1008+F1008+G1008),0) -> 0.5
A1009: O2 – Increased confidence to report | E1009: =COUNTIF(F5:F1004,"Yes") -> 3 | F1009: =COUNTIF(F5:F1004,"Partial") -> 0 | G1009: =COUNTIF(F5:F1004,"No") -> 7 | H1009: =COUNTIF(F5:F1004,"N/A") -> 0 | I1009: =IFERROR(E1009/(E1009+F1009+G1009),0) -> 0.3
A1010: O3 – Strengthened partnership engaged | E1010: =COUNTIF(G5:G1004,"Yes") -> 1 | F1010: =COUNTIF(G5:G1004,"Partial") -> 0 | G1010: =COUNTIF(G5:G1004,"No") -> 9 | H1010: =COUNTIF(G5:G1004,"N/A") -> 0 | I1010: =IFERROR(E1010/(E1010+F1010+G1010),0) -> 0.1
A1011: O4 – Increased awareness of HC | E1011: =COUNTIF(H5:H1004,"Yes") -> 6 | F1011: =COUNTIF(H5:H1004,"Partial") -> 0 | G1011: =COUNTIF(H5:H1004,"No") -> 4 | H1011: =COUNTIF(H5:H1004,"N/A") -> 0 | I1011: =IFERROR(E1011/(E1011+F1011+G1011),0) -> 0.6
A1012: O5 – Community-led solution initiated | E1012: =COUNTIF(I5:I1004,"Yes") -> 0 | F1012: =COUNTIF(I5:I1004,"Partial") -> 0 | G1012: =COUNTIF(I5:I1004,"No") -> 10 | H1012: =COUNTIF(I5:I1004,"N/A") -> 0 | I1012: =IFERROR(E1012/(E1012+F1012+G1012),0) -> 0

Sheet 🔀 Referral Tracker
A1: REFERRAL TRACKER | Hate Crime Support Project | WLEC
A2: Track all incoming referrals TO the project and outgoing referrals FROM the project to partner services.
A4: REFERRAL SOURCE SUMMARY — Auto-calculated from log below
A5: Referral Source | E5: Count | H5: % of Total | K5: Year 1 | L5: Year 2 | M5: Year 3 | N5: Year 4 | O5: Year 5
A6: Victim Support | E6: =COUNTIFS('📋 Client Intake'!H5:H1004,A6) -> 1 | H6: =IFERROR(E6/SUM(E6:E22),0) -> 0.2 | K6: =COUNTIFS('📋 Client Intake'!H5:H1004,A6,'📋 Client Intake'!AB5:AB1004,"Year 1") -> 0 | L6: =COUNTIFS('📋 Client Intake'!H5:H1004,A6,'📋 Client Intake'!AB5:AB1004,"Year 2") -> 1 | M6: =COUNTIFS('📋 Client Intake'!H5:H1004,A6,'📋 Client Intake'!AB5:AB1004,"Year 3") -> 0 | N6: =COUNTIFS('📋 Client Intake'!H5:H1004,A6,'📋 Client Intake'!AB5:AB1004,"Year 4") -> 0 | O6: =COUNTIFS('📋 Client Intake'!H5:H1004,A6,'📋 Client Intake'!AB5:AB1004,"Year 5") -> 0
A7: Age UK | E7: =COUNTIFS('📋 Client Intake'!H5:H1004,A7) -> 0 | H7: =IFERROR(E7/SUM(E6:E22),0) -> 0 | K7: =COUNTIFS('📋 Client Intake'!H5:H1004,A7,'📋 Client Intake'!AB5:AB1004,"Year 1") -> 0 | L7: =COUNTIFS('📋 Client Intake'!H5:H1004,A7,'📋 Client Intake'!AB5:AB1004,"Year 2") -> 0 | M7: =COUNTIFS('📋 Client Intake'!H5:H1004,A7,'📋 Client Intake'!AB5:AB1004,"Year 3") -> 0 | N7: =COUNTIFS('📋 Client Intake'!H5:H1004,A7,'📋 Client Intake'!AB5:AB1004,"Year 4") -> 0 | O7: =COUNTIFS('📋 Client Intake'!H5:H1004,A7,'📋 Client Intake'!AB5:AB1004,"Year 5") -> 0
A8: MENCAP | E8: =COUNTIFS('📋 Client Intake'!H5:H1004,A8) -> 0 | H8: =IFERROR(E8/SUM(E6:E22),0) -> 0 | K8: =COUNTIFS('📋 Client Intake'!H5:H1004,A8,'📋 Client Intake'!AB5:AB1004,"Year 1") -> 0 | L8: =COUNTIFS('📋 Client Intake'!H5:H1004,A8,'📋 Client Intake'!AB5:AB1004,"Year 2") -> 0 | M8: =COUNTIFS('📋 Client Intake'!H5:H1004,A8,'📋 Client Intake'!AB5:AB1004,"Year 3") -> 0 | N8: =COUNTIFS('📋 Client Intake'!H5:H1004,A8,'📋 Client Intake'!AB5:AB1004,"Year 4") -> 0 | O8: =COUNTIFS('📋 Client Intake'!H5:H1004,A8,'📋 Client Intake'!AB5:AB1004,"Year 5") -> 0
A9: Spectra | E9: =COUNTIFS('📋 Client Intake'!H5:H1004,A9) -> 0 | H9: =IFERROR(E9/SUM(E6:E22),0) -> 0 | K9: =COUNTIFS('📋 Client Intake'!H5:H1004,A9,'📋 Client Intake'!AB5:AB1004,"Year 1") -> 0 | L9: =COUNTIFS('📋 Client Intake'!H5:H1004,A9,'📋 Client Intake'!AB5:AB1004,"Year 2") -> 0 | M9: =COUNTIFS('📋 Client Intake'!H5:H1004,A9,'📋 Client Intake'!AB5:AB1004,"Year 3") -> 0 | N9: =COUNTIFS('📋 Client Intake'!H5:H1004,A9,'📋 Client Intake'!AB5:AB1004,"Year 4") -> 0 | O9: =COUNTIFS('📋 Client Intake'!H5:H1004,A9,'📋 Client Intake'!AB5:AB1004,"Year 5") -> 0
A10: ECIL | E10: =COUNTIFS('📋 Client Intake'!H5:H1004,A10) -> 0 | H10: =IFERROR(E10/SUM(E6:E22),0) -> 0 | K10: =COUNTIFS('📋 Client Intake'!H5:H1004,A10,'📋 Client Intake'!AB5:AB1004,"Year 1") -> 0 | L10: =COUNTIFS('📋 Client Intake'!H5:H1004,A10,'📋 Client Intake'!AB5:AB1004,"Year 2") -> 0 | M10: =COUNTIFS('📋 Client Intake'!H5:H1004,A10,'📋 Client Intake'!AB5:AB1004,"Year 3") -> 0 | N10: =COUNTIFS('📋 Client Intake'!H5:H1004,A10,'📋 Client Intake'!AB5:AB1004,"Year 4") -> 0 | O10: =COUNTIFS('📋 Client Intake'!H5:H1004,A10,'📋 Client Intake'!AB5:AB1004,"Year 5") -> 0
A11: MPS (Police) | E11: =COUNTIFS('📋 Client Intake'!H5:H1004,A11) -> 1 | H11: =IFERROR(E11/SUM(E6:E22),0) -> 0.2 | K11: =COUNTIFS('📋 Client Intake'!H5:H1004,A11,'📋 Client Intake'!AB5:AB1004,"Year 1") -> 1 | L11: =COUNTIFS('📋 Client Intake'!H5:H1004,A11,'📋 Client Intake'!AB5:AB1004,"Year 2") -> 0 | M11: =COUNTIFS('📋 Client Intake'!H5:H1004,A11,'📋 Client Intake'!AB5:AB1004,"Year 3") -> 0 | N11: =COUNTIFS('📋 Client Intake'!H5:H1004,A11,'📋 Client Intake'!AB5:AB1004,"Year 4") -> 0 | O11: =COUNTIFS('📋 Client Intake'!H5:H1004,A11,'📋 Client Intake'!AB5:AB1004,"Year 5") -> 0
A12: Local MP / Councillor | E12: =COUNTIFS('📋 Client Intake'!H5:H1004,A12) -> 0 | H12: =IFERROR(E12/SUM(E6:E22),0) -> 0 | K12: =COUNTIFS('📋 Client Intake'!H5:H1004,A12,'📋 Client Intake'!AB5:AB1004,"Year 1") -> 0 | L12: =COUNTIFS('📋 Client Intake'!H5:H1004,A12,'📋 Client Intake'!AB5:AB1004,"Year 2") -> 0 | M12: =COUNTIFS('📋 Client Intake'!H5:H1004,A12,'📋 Client Intake'!AB5:AB1004,"Year 3") -> 0 | N12: =COUNTIFS('📋 Client Intake'!H5:H1004,A12,'📋 Client Intake'!AB5:AB1004,"Year 4") -> 0 | O12: =COUNTIFS('📋 Client Intake'!H5:H1004,A12,'📋 Client Intake'!AB5:AB1004,"Year 5") -> 0
A13: Self-Referral | E13: =COUNTIFS('📋 Client Intake'!H5:H1004,A13) -> 1 | H13: =IFERROR(E13/SUM(E6:E22),0) -> 0.2 | K13: =COUNTIFS('📋 Client Intake'!H5:H1004,A13,'📋 Client Intake'!AB5:AB1004,"Year 1") -> 1 | L13: =COUNTIFS('📋 Client Intake'!H5:H1004,A13,'📋 Client Intake'!AB5:AB1004,"Year 2") -> 0 | M13: =COUNTIFS('📋 Client Intake'!H5:H1004,A13,'📋 Client Intake'!AB5:AB1004,"Year 3") -> 0 | N13: =COUNTIFS('📋 Client Intake'!H5:H1004,A13,'📋 Client Intake'!AB5:AB1004,"Year 4") -> 0 | O13: =COUNTIFS('📋 Client Intake'!H5:H1004,A13,'📋 Client Intake'!AB5:AB1004,"Year 5") -> 0
A14: CATCH | E14: =COUNTIFS('📋 Client Intake'!H5:H1004,A14) -> 0 | H14: =IFERROR(E14/SUM(E6:E22),0) -> 0 | K14: =COUNTIFS('📋 Client Intake'!H5:H1004,A14,'📋 Client Intake'!AB5:AB1004,"Year 1") -> 0 | L14: =COUNTIFS('📋 Client Intake'!H5:H1004,A14,'📋 Client Intake'!AB5:AB1004,"Year 2") -> 0 | M14: =COUNTIFS('📋 Client Intake'!H5:H1004,A14,'📋 Client Intake'!AB5:AB1004,"Year 3") -> 0 | N14: =COUNTIFS('📋 Client Intake'!H5:H1004,A14,'📋 Client Intake'!AB5:AB1004,"Year 4") -> 0 | O14: =COUNTIFS('📋 Client Intake'!H5:H1004,A14,'📋 Client Intake'!AB5:AB1004,"Year 5") -> 0
A15: Community Security Trust | E15: =COUNTIFS('📋 Client Intake'!H5:H1004,A15) -> 0 | H15: =IFERROR(E15/SUM(E6:E22),0) -> 0 | K15: =COUNTIFS('📋 Client Intake'!H5:H1004,A15,'📋 Client Intake'!AB5:AB1004,"Year 1") -> 0 | L15: =COUNTIFS('📋 Client Intake'!H5:H1004,A15,'📋 Client Intake'!AB5:AB1004,"Year 2") -> 0 | M15: =COUNTIFS('📋 Client Intake'!H5:H1004,A15,'📋 Client Intake'!AB5:AB1004,"Year 3") -> 0 | N15: =COUNTIFS('📋 Client Intake'!H5:H1004,A15,'📋 Client Intake'!AB5:AB1004,"Year 4") -> 0 | O15: =COUNTIFS('📋 Client Intake'!H5:H1004,A15,'📋 Client Intake'!AB5:AB1004,"Year 5") -> 0
A16: Galop | E16: =COUNTIFS('📋 Client Intake'!H5:H1004,A16) -> 0 | H16: =IFERROR(E16/SUM(E6:E22),0) -> 0 | K16: =COUNTIFS('📋 Client Intake'!H5:H1004,A16,'📋 Client Intake'!AB5:AB1004,"Year 1") -> 0 | L16: =COUNTIFS('📋 Client Intake'!H5:H1004,A16,'📋 Client Intake'!AB5:AB1004,"Year 2") -> 0 | M16: =COUNTIFS('📋 Client Intake'!H5:H1004,A16,'📋 Client Intake'!AB5:AB1004,"Year 3") -> 0 | N16: =COUNTIFS('📋 Client Intake'!H5:H1004,A16,'📋 Client Intake'!AB5:AB1004,"Year 4") -> 0 | O16: =COUNTIFS('📋 Client Intake'!H5:H1004,A16,'📋 Client Intake'!AB5:AB1004,"Year 5") -> 0
A17: MARAC | E17: =COUNTIFS('📋 Client Intake'!H5:H1004,A17) -> 0 | H17: =IFERROR(E17/SUM(E6:E22),0) -> 0 | K17: =COUNTIFS('📋 Client Intake'!H5:H1004,A17,'📋 Client Intake'!AB5:AB1004,"Year 1") -> 0 | L17: =COUNTIFS('📋 Client Intake'!H5:H1004,A17,'📋 Client Intake'!AB5:AB1004,"Year 2") -> 0 | M17: =COUNTIFS('📋 Client Intake'!H5:H1004,A17,'📋 Client Intake'!AB5:AB1004,"Year 3") -> 0 | N17: =COUNTIFS('📋 Client Intake'!H5:H1004,A17,'📋 Client Intake'!AB5:AB1004,"Year 4") -> 0 | O17: =COUNTIFS('📋 Client Intake'!H5:H1004,A17,'📋 Client Intake'!AB5:AB1004,"Year 5") -> 0
A18: Housing Association | E18: =COUNTIFS('📋 Client Intake'!H5:H1004,A18) -> 0 | H18: =IFERROR(E18/SUM(E6:E22),0) -> 0 | K18: =COUNTIFS('📋 Client Intake'!H5:H1004,A18,'📋 Client Intake'!AB5:AB1004,"Year 1") -> 0 | L18: =COUNTIFS('📋 Client Intake'!H5:H1004,A18,'📋 Client Intake'!AB5:AB1004,"Year 2") -> 0 | M18: =COUNTIFS('📋 Client Intake'!H5:H1004,A18,'📋 Client Intake'!AB5:AB1004,"Year 3") -> 0 | N18: =COUNTIFS('📋 Client Intake'!H5:H1004,A18,'📋 Client Intake'!AB5:AB1004,"Year 4") -> 0 | O18: =COUNTIFS('📋 Client Intake'!H5:H1004,A18,'📋 Client Intake'!AB5:AB1004,"Year 5") -> 0
A19: Council Safer Communities | E19: =COUNTIFS('📋 Client Intake'!H5:H1004,A19) -> 0 | H19: =IFERROR(E19/SUM(E6:E22),0) -> 0 | K19: =COUNTIFS('📋 Client Intake'!H5:H1004,A19,'📋 Client Intake'!AB5:AB1004,"Year 1") -> 0 | L19: =COUNTIFS('📋 Client Intake'!H5:H1004,A19,'📋 Client Intake'!AB5:AB1004,"Year 2") -> 0 | M19: =COUNTIFS('📋 Client Intake'!H5:H1004,A19,'📋 Client Intake'!AB5:AB1004,"Year 3") -> 0 | N19: =COUNTIFS('📋 Client Intake'!H5:H1004,A19,'📋 Client Intake'!AB5:AB1004,"Year 4") -> 0 | O19: =COUNTIFS('📋 Client Intake'!H5:H1004,A19,'📋 Client Intake'!AB5:AB1004,"Year 5") -> 0
A20: Citizens Advice | E20: =COUNTIFS('📋 Client Intake'!H5:H1004,A20) -> 1 | H20: =IFERROR(E20/SUM(E6:E22),0) -> 0.2 | K20: =COUNTIFS('📋 Client Intake'!H5:H1004,A20,'📋 Client Intake'!AB5:AB1004,"Year 1") -> 1 | L20: =COUNTIFS('📋 Client Intake'!H5:H1004,A20,'📋 Client Intake'!AB5:AB1004,"Year 2") -> 0 | M20: =COUNTIFS('📋 Client Intake'!H5:H1004,A20,'📋 Client Intake'!AB5:AB1004,"Year 3") -> 0 | N20: =COUNTIFS('📋 Client Intake'!H5:H1004,A20,'📋 Client Intake'!AB5:AB1004,"Year 4") -> 0 | O20: =COUNTIFS('📋 Client Intake'!H5:H1004,A20,'📋 Client Intake'!AB5:AB1004,"Year 5") -> 0
A21: Legal Aid Organisation | E21: =COUNTIFS('📋 Client Intake'!H5:H1004,A21) -> 0 | H21: =IFERROR(E21/SUM(E6:E22),0) -> 0 | K21: =COUNTIFS('📋 Client Intake'!H5:H1004,A21,'📋 Client Intake'!AB5:AB1004,"Year 1") -> 0 | L21: =COUNTIFS('📋 Client Intake'!H5:H1004,A21,'📋 Client Intake'!AB5:AB1004,"Year 2") -> 0 | M21: =COUNTIFS('📋 Client Intake'!H5:H1004,A21,'📋 Client Intake'!AB5:AB1004,"Year 3") -> 0 | N21: =COUNTIFS('📋 Client Intake'!H5:H1004,A21,'📋 Client Intake'!AB5:AB1004,"Year 4") -> 0 | O21: =COUNTIFS('📋 Client Intake'!H5:H1004,A21,'📋 Client Intake'!AB5:AB1004,"Year 5") -> 0
A22: Other | E22: =COUNTIFS('📋 Client Intake'!H5:H1004,A22) -> 1 | H22: =IFERROR(E22/SUM(E6:E22),0) -> 0.2 | K22: =COUNTIFS('📋 Client Intake'!H5:H1004,A22,'📋 Client Intake'!AB5:AB1004,"Year 1") -> 1 | L22: =COUNTIFS('📋 Client Intake'!H5:H1004,A22,'📋 Client Intake'!AB5:AB1004,"Year 2") -> 0 | M22: =COUNTIFS('📋 Client Intake'!H5:H1004,A22,'📋 Client Intake'!AB5:AB1004,"Year 3") -> 0 | N22: =COUNTIFS('📋 Client Intake'!H5:H1004,A22,'📋 Client Intake'!AB5:AB1004,"Year 4") -> 0 | O22: =COUNTIFS('📋 Client Intake'!H5:H1004,A22,'📋 Client Intake'!AB5:AB1004,"Year 5") -> 0
A23: TOTAL | E23: =SUM(E6:E22) -> 5
A25: REFERRAL LOG — Add each referral below
A26: Date | B26: Client Ref | C26: Initials | D26: Direction | E26: Referred By / To | F26: Reason | G26: Borough | H26: Risk | I26: Date Ack'd | J26: Date Actioned | K26: Outcome | L26: Follow-up? | M26: Follow-up Date | N26: Caseworker | O26: Year | P26: Notes

Sheet 📅 Activities
A1: PROJECT ACTIVITIES & DELIVERABLES | Hate Crime Support Project | WLEC
A3: 5-YEAR ACTIVITY TARGETS (from M&E Framework)
A4: Activity | B4: Y1 Target | C4: Y2 Target | D4: Y3 Target | E4: Y4 Target | F4: Y5 Target | G4: Actual to Date | H4: % of Y5 Target
A5: Hate crime cases handled | B5: 50 | C5: 50 | D5: 50 | E5: 50 | F5: 50 | G5: 4 | H5: =IFERROR(G5/F5,0) -> 0.08
A6: Awareness workshops delivered | B6: 10 | C6: 15 | D6: 15 | E6: 15 | F6: 15 | G6: 1 | H6: =IFERROR(G6/F6,0) -> 0.066666667
A7: New volunteers recruited | B7: 0 | C7: 15 | D7: 0 | E7: 0 | F7: 0 | G7: 0 | H7: =IFERROR(G7/F7,0) -> 0
A8: Formal agency partnerships | B8: 5 | C8: 10 | D8: 15 | E8: 18 | F8: 20 | G8: 0 | H8: =IFERROR(G8/F8,0) -> 0
A9: Community-led initiatives | B9: 0 | C9: 2 | D9: 5 | E9: 7 | F9: 10 | G9: 0 | H9: =IFERROR(G9/F9,0) -> 0
A10: Beneficiary surveys completed | B10: 50 | C10: 50 | D10: 50 | E10: 50 | F10: 50 | G10: 0 | H10: =IFERROR(G10/F10,0) -> 0
A11: Training sessions delivered | B11: 10 | C11: 15 | D11: 15 | E11: 15 | F11: 15 | G11: 1 | H11: =IFERROR(G11/F11,0) -> 0.066666667
A12: Stakeholder interviews (annual) | B12: 0 | C12: 1 | D12: 1 | E12: 1 | F12: 1 | G12: 0 | H12: =IFERROR(G12/F12,0) -> 0
A13: Community feedback forums | B13: 2 | C13: 4 | D13: 4 | E13: 4 | F13: 4 | G13: 0 | H13: =IFERROR(G13/F13,0) -> 0
A14: Policy recommendations published | B14: 0 | C14: 0 | D14: 0 | E14: 1 | F14: 1 | G14: 0 | H14: =IFERROR(G14/F14,0) -> 0
A16: ACTIVITY LOG — Add each event or session below
A17: Date | B17: Activity Title | C17: Activity Type | D17: Borough | E17: Location / Venue | F17: Lead Worker | G17: Participants | H17: New Referrals Generated | I17: Project Year | J17: Outcome / Notes
A18: 46067 | B18: Hate Crime Awareness Workshop – Ealing | C18: Workshop | D18: Ealing | E18: Ealing Civic Centre, New Broadway | F18: Omer Ul-haque | G18: 35 | H18: 3 | I18: Year 1 | J18: O4: Increased Awareness of HC
A19: 46089 | B19: Caseworker Training Session – WLEC | C19: Training Session | D19: Ealing | E19: WLEC Office, Uxbridge Road | F19: Reena Malhan | G19: 12 | H19: 0 | I19: Year 1 | J19: O1: Better Access to Legal Support

Sheet 🙋 Volunteer Log
A1: VOLUNTEER LOG | Hate Crime Support Project | WLEC
A2: Track all volunteers, their training status, hours, DBS, and activity. Numbers feed Dashboard and Quarterly Report automatically.
A4: ⚡ VOLUNTEER SUMMARY — Auto-calculated
A5: Total Volunteers Registered | E5: Currently Active | I5: Total Hours Volunteered | M5: Fully Trained (All Modules)
A6: =COUNTA(B12:B211) -> 4 | E6: =COUNTIF(G12:G211,"Active") -> 4 | I6: =SUM(J12:J211) -> 54 | M6: =COUNTIF(F12:F211,"Complete") -> 0
A10: VOLUNTEER REGISTER — One row per volunteer
A11: Ref | B11: Full Name | C11: Role / Specialism | D11: Date Joined | E11: Borough(s) | F11: Training Status | G11: Status | H11: DBS Date | I11: DBS Expiry | J11: Total Hours | K11: Cases Supported | L11: Activities Led | M11: Languages | N11: Accessibility Needs | O11: Year Joined | P11: Notes
A12: VOL-001 | B12: Freda Ritchie 1 | C12: Community Outreach Volunteer | D12: 45962 | E12: Ealing | F12: Fully Trained | G12: Active | H12: 45945 | I12: 46675 | J12: 24 | K12: 3 | L12: 2 | M12: English | N12: None | O12: Year 1 | P12: Freda Ritchie Test 1 — Volunteer since project launch
A13: VOL-002 | B13: Freda Ritchie 2 | C13: Legal Support Volunteer | D13: 46032 | E13: Hillingdon | F13: In Progress | G13: Active | H13: 45992 | I13: 46722 | J13: 16 | K13: 2 | L13: 1 | M13: English, Urdu | N13: None | O13: Year 1 | P13: Freda Ritchie Test 2 — Bilingual volunteer, training modules 1-4 complete
A14: VOL-003 | B14: Freda Ritchie 3 | C14: Admin & Data Support Volunteer | D14: 46086 | E14: Ealing | F14: Fully Trained | G14: Active | H14: 46073 | I14: 46803 | J14: 10 | K14: 0 | L14: 1 | M14: English | N14: None | O14: Year 1 | P14: Freda Ritchie Test 3 — Assists with client intake data entry
A15: VOL-004 | B15: Freda Ritchie 4 | C15: Community Liaison Volunteer | D15: 46341 | E15: Hounslow | F15: Not Started | G15: Active | H15: 46325 | I15: 47056 | J15: 4 | K15: 1 | L15: 0 | M15: English, Somali | N15: None | O15: Year 2 | P15: Freda Ritchie Test 4 — Year 2 recruit, training not yet commenced
A220: VOLUNTEER HOURS LOG — Record each session
A221: Date | B221: Ref | C221: Name | D221: Activity / Task | E221: Activity Type | F221: Borough | G221: Hours | H221: Supervised By | I221: Notes

Sheet 🎓 Training Register
A1: TRAINING REGISTER | Hate Crime Support Project | WLEC
A2: Record every training session delivered — staff, volunteers, and partner/community training.
A4: ⚡ TRAINING SUMMARY
A5: Total Sessions Delivered | E5: Total Participants | I5: Staff Trained | M5: Volunteers Trained | Q5: Partners Trained
A6: =COUNTA(B10:B500) -> 5 | E6: =SUM(H10:H500) -> 87 | I6: =COUNTIF(D10:D500,"Staff") -> 1 | M6: =COUNTIF(D10:D500,"Volunteer") -> 0 | Q6: =COUNTIF(D10:D500,"Partner/Community") -> 0
A9: TRAINING SESSION LOG
A10: Date | B10: Training Title | C10: Topic / Content | D10: Audience | E10: Year | F10: Delivered By | G10: Location | H10: Participants | I10: Hours | J10: Borough | K10: Method | L10: Pre-Assessment | M10: Post-Assessment | N10: Certificate? | O10: Feedback (1-5) | P10: Evidence Ref | Q10: Follow-up? | R10: Notes
A11: 46067 | B11: Hate Crime Awareness & Reporting (Test: Freda Ritchie 1) | C11: Definition of hate crime, reporting pathways, victim support | D11: Staff & Volunteers | E11: Year 1 | F11: Freda Ritchie | G11: Ealing Civic Centre, New Broadway | H11: 35 | I11: 3 | J11: Ealing | K11: In-person | L11: 3 | M11: 4 | N11: Yes | O11: 5 | P11: HCSP-TR-001 | Q11: No | R11: Freda Ritchie Test 1 — Workshop linked to awareness campaign
A12: 46089 | B12: Caseworker Skills Training (Test: Freda Ritchie 2) | C12: Case recording, outcome measurement, client confidentiality | D12: Staff | E12: Year 1 | F12: Freda Ritchie | G12: WLEC Office, Uxbridge Road | H12: 12 | I12: 2.5 | J12: Ealing | K12: In-person | L12: 3 | M12: 5 | N12: Yes | O12: 4 | P12: HCSP-TR-002 | Q12: No | R12: Freda Ritchie Test 2 — Internal staff training on M&E system
A13: 46162 | B13: Online Safety & Cyber Hate (Test: Freda Ritchie 3) | C13: Online hate crime, evidence gathering, reporting to platforms | D13: Community & Volunteers | E13: Year 1 | F13: Freda Ritchie | G13: Zoom (Online) | H13: 22 | I13: 2 | J13: Other West London | K13: Online | L13: 2 | M13: 4 | N13: No | O13: 4 | P13: HCSP-TR-003 | Q13: Yes | R13: Freda Ritchie Test 3 — Follow-up session planned for Q3
A14: 46336 | B14: Partnership & Referral Pathways (Test: Freda Ritchie 4) | C14: Working with statutory agencies, referral protocols, data sharing | D14: Staff & Partners | E14: Year 2 | F14: Freda Ritchie | G14: Hillingdon Civic Centre | H14: 18 | I14: 3 | J14: Hillingdon | K14: In-person | L14: 3 | M14: 5 | N14: Yes | O14: 5 | P14: HCSP-TR-004 | Q14: No | R14: Freda Ritchie Test 4 — Year 2 partner agency training
A515: VOLUNTEER TRAINING COMPLETION MATRIX — ✅ = Complete ⬜ = Outstanding
A516: Volunteer Name | B516: HC Law & Legislation | C516: Safeguarding | D516: Unconscious Bias | E516: Trauma- Informed | F516: GDPR / Data Protection | G516: Community Trigger | H516: LGBTQI+ Awareness | I516: Disability HC | J516: % Complete
B517: ⬜ | C517: ⬜ | D517: ⬜ | E517: ⬜ | F517: ⬜ | G517: ⬜ | H517: ⬜ | I517: ⬜ | J517: =COUNTIF(B517:I517,"✅")/8 -> 0
B518: ⬜ | C518: ⬜ | D518: ⬜ | E518: ⬜ | F518: ⬜ | G518: ⬜ | H518: ⬜ | I518: ⬜ | J518: =COUNTIF(B518:I518,"✅")/8 -> 0
B519: ⬜ | C519: ⬜ | D519: ⬜ | E519: ⬜ | F519: ⬜ | G519: ⬜ | H519: ⬜ | I519: ⬜ | J519: =COUNTIF(B519:I519,"✅")/8 -> 0
B520: ⬜ | C520: ⬜ | D520: ⬜ | E520: ⬜ | F520: ⬜ | G520: ⬜ | H520: ⬜ | I520: ⬜ | J520: =COUNTIF(B520:I520,"✅")/8 -> 0
B521: ⬜ | C521: ⬜ | D521: ⬜ | E521: ⬜ | F521: ⬜ | G521: ⬜ | H521: ⬜ | I521: ⬜ | J521: =COUNTIF(B521:I521,"✅")/8 -> 0
B522: ⬜ | C522: ⬜ | D522: ⬜ | E522: ⬜ | F522: ⬜ | G522: ⬜ | H522: ⬜ | I522: ⬜ | J522: =COUNTIF(B522:I522,"✅")/8 -> 0
B523: ⬜ | C523: ⬜ | D523: ⬜ | E523: ⬜ | F523: ⬜ | G523: ⬜ | H523: ⬜ | I523: ⬜ | J523: =COUNTIF(B523:I523,"✅")/8 -> 0
B524: ⬜ | C524: ⬜ | D524: ⬜ | E524: ⬜ | F524: ⬜ | G524: ⬜ | H524: ⬜ | I524: ⬜ | J524: =COUNTIF(B524:I524,"✅")/8 -> 0
B525: ⬜ | C525: ⬜ | D525: ⬜ | E525: ⬜ | F525: ⬜ | G525: ⬜ | H525: ⬜ | I525: ⬜ | J525: =COUNTIF(B525:I525,"✅")/8 -> 0
B526: ⬜ | C526: ⬜ | D526: ⬜ | E526: ⬜ | F526: ⬜ | G526: ⬜ | H526: ⬜ | I526: ⬜ | J526: =COUNTIF(B526:I526,"✅")/8 -> 0
B527: ⬜ | C527: ⬜ | D527: ⬜ | E527: ⬜ | F527: ⬜ | G527: ⬜ | H527: ⬜ | I527: ⬜ | J527: =COUNTIF(B527:I527,"✅")/8 -> 0
B528: ⬜ | C528: ⬜ | D528: ⬜ | E528: ⬜ | F528: ⬜ | G528: ⬜ | H528: ⬜ | I528: ⬜ | J528: =COUNTIF(B528:I528,"✅")/8 -> 0
... B536: ⬜ | C536: ⬜ | D536: ⬜ | E536: ⬜ | F536: ⬜ | G536: ⬜ | H536: ⬜ | I536: ⬜ | J536: =COUNTIF(B536:I536,"✅")/8 -> 0

Sheet 📈 KPI Trends
A1: KPI TREND CHARTS | 5-Year Progress | Hate Crime Support Project | WLEC
A2: Update yellow cells with actual data each year/quarter. Charts update automatically. Use for funder reports and annual reviews.
A4: TABLE 1 — Cases Handled Per Year vs Target | M4: TABLE 2 — Outcome Achievement Per Year (% of beneficiaries)
A5: Metric | B5: Y1 Target | C5: Y1 Actual | D5: Y2 Target | E5: Y2 Actual | F5: Y3 Target | G5: Y3 Actual | H5: Y4 Target | I5: Y4 Actual | J5: Y5 Target | K5: Y5 Actual | M5: Outcome | N5: Y1 | O5: Y2 | P5: Y3 | Q5: Y4 | R5: Y5 | S5: 5-Yr Target
A6: Cases Handled | B6: 50 | C6: =COUNTIFS('📋 Client Intake'!AB5:AB1004,"Year 1") -> 4 | D6: 100 | E6: =COUNTIFS('📋 Client Intake'!AB5:AB1004,"Year 2") -> 2 | F6: 150 | G6: =COUNTIFS('📋 Client Intake'!AB5:AB1004,"Year 3") -> 0 | H6: 200 | I6: =COUNTIFS('📋 Client Intake'!AB5:AB1004,"Year 4") -> 0 | J6: 250 | K6: =COUNTIFS('📋 Client Intake'!AB5:AB1004,"Year 5") -> 0 | M6: O1 – Better access to legal support | N6: =IFERROR(COUNTIFS('📊 Outcome Tracker'!E5:E1004,"Yes",'📊 Outcome Tracker'!H5:H1004,"Year 1")/COUNTIFS('📊 Outcome Tracker'!H5:H1004,"Year 1",'📊 Outcome Tracker'!A5:A1004,"<>"""),0) -> 0 | O6: =IFERROR(COUNTIFS('📊 Outcome Tracker'!E5:E1004,"Yes",'📊 Outcome Tracker'!H5:H1004,"Year 2")/COUNTIFS('📊 Outcome Tracker'!H5:H1004,"Year 2",'📊 Outcome Tracker'!A5:A1004,"<>"""),0) -> 0 | P6: =IFERROR(COUNTIFS('📊 Outcome Tracker'!E5:E1004,"Yes",'📊 Outcome Tracker'!H5:H1004,"Year 3")/COUNTIFS('📊 Outcome Tracker'!H5:H1004,"Year 3",'📊 Outcome Tracker'!A5:A1004,"<>"""),0) -> 0 | Q6: =IFERROR(COUNTIFS('📊 Outcome Tracker'!E5:E1004,"Yes",'📊 Outcome Tracker'!H5:H1004,"Year 4")/COUNTIFS('📊 Outcome Tracker'!H5:H1004,"Year 4",'📊 Outcome Tracker'!A5:A1004,"<>"""),0) -> 0 | R6: =IFERROR(COUNTIFS('📊 Outcome Tracker'!E5:E1004,"Yes",'📊 Outcome Tracker'!H5:H1004,"Year 5")/COUNTIFS('📊 Outcome Tracker'!H5:H1004,"Year 5",'📊 Outcome Tracker'!A5:A1004,"<>"""),0) -> 0 | S6: 80%
A7: Workshops Delivered | B7: 10 | C7: =COUNTIFS('📅 Activities'!C18:C1000,"Workshop",'📅 Activities'!I18:I1000,"Year 1") -> 1 | D7: 15 | E7: =COUNTIFS('📅 Activities'!C18:C1000,"Workshop",'📅 Activities'!I18:I1000,"Year 2") -> 0 | F7: 15 | G7: =COUNTIFS('📅 Activities'!C18:C1000,"Workshop",'📅 Activities'!I18:I1000,"Year 3") -> 0 | H7: 15 | I7: =COUNTIFS('📅 Activities'!C18:C1000,"Workshop",'📅 Activities'!I18:I1000,"Year 4") -> 0 | J7: 15 | K7: =COUNTIFS('📅 Activities'!C18:C1000,"Workshop",'📅 Activities'!I18:I1000,"Year 5") -> 0 | M7: O2 – Confident to report | N7: =IFERROR(COUNTIFS('📊 Outcome Tracker'!F5:F1004,"Yes",'📊 Outcome Tracker'!H5:H1004,"Year 1")/COUNTIFS('📊 Outcome Tracker'!H5:H1004,"Year 1",'📊 Outcome Tracker'!A5:A1004,"<>"""),0) -> 0 | O7: =IFERROR(COUNTIFS('📊 Outcome Tracker'!F5:F1004,"Yes",'📊 Outcome Tracker'!H5:H1004,"Year 2")/COUNTIFS('📊 Outcome Tracker'!H5:H1004,"Year 2",'📊 Outcome Tracker'!A5:A1004,"<>"""),0) -> 0 | P7: =IFERROR(COUNTIFS('📊 Outcome Tracker'!F5:F1004,"Yes",'📊 Outcome Tracker'!H5:H1004,"Year 3")/COUNTIFS('📊 Outcome Tracker'!H5:H1004,"Year 3",'📊 Outcome Tracker'!A5:A1004,"<>"""),0) -> 0 | Q7: =IFERROR(COUNTIFS('📊 Outcome Tracker'!F5:F1004,"Yes",'📊 Outcome Tracker'!H5:H1004,"Year 4")/COUNTIFS('📊 Outcome Tracker'!H5:H1004,"Year 4",'📊 Outcome Tracker'!A5:A1004,"<>"""),0) -> 0 | R7: =IFERROR(COUNTIFS('📊 Outcome Tracker'!F5:F1004,"Yes",'📊 Outcome Tracker'!H5:H1004,"Year 5")/COUNTIFS('📊 Outcome Tracker'!H5:H1004,"Year 5",'📊 Outcome Tracker'!A5:A1004,"<>"""),0) -> 0 | S7: 60%
A8: New Partnerships | B8: 5 | C8: 0 | D8: 10 | E8: 0 | F8: 15 | G8: 0 | H8: 18 | I8: 0 | J8: 20 | K8: 0 | M8: O3 – Partnership strengthened | N8: =IFERROR(COUNTIFS('📊 Outcome Tracker'!G5:G1004,"Yes",'📊 Outcome Tracker'!H5:H1004,"Year 1")/COUNTIFS('📊 Outcome Tracker'!H5:H1004,"Year 1",'📊 Outcome Tracker'!A5:A1004,"<>"""),0) -> 0 | O8: =IFERROR(COUNTIFS('📊 Outcome Tracker'!G5:G1004,"Yes",'📊 Outcome Tracker'!H5:H1004,"Year 2")/COUNTIFS('📊 Outcome Tracker'!H5:H1004,"Year 2",'📊 Outcome Tracker'!A5:A1004,"<>"""),0) -> 0 | P8: =IFERROR(COUNTIFS('📊 Outcome Tracker'!G5:G1004,"Yes",'📊 Outcome Tracker'!H5:H1004,"Year 3")/COUNTIFS('📊 Outcome Tracker'!H5:H1004,"Year 3",'📊 Outcome Tracker'!A5:A1004,"<>"""),0) -> 0 | Q8: =IFERROR(COUNTIFS('📊 Outcome Tracker'!G5:G1004,"Yes",'📊 Outcome Tracker'!H5:H1004,"Year 4")/COUNTIFS('📊 Outcome Tracker'!H5:H1004,"Year 4",'📊 Outcome Tracker'!A5:A1004,"<>"""),0) -> 0 | R8: =IFERROR(COUNTIFS('📊 Outcome Tracker'!G5:G1004,"Yes",'📊 Outcome Tracker'!H5:H1004,"Year 5")/COUNTIFS('📊 Outcome Tracker'!H5:H1004,"Year 5",'📊 Outcome Tracker'!A5:A1004,"<>"""),0) -> 0 | S8: 20%
M9: O4 – Increased awareness | N9: =IFERROR(COUNTIFS('📊 Outcome Tracker'!H5:H1004,"Yes",'📊 Outcome Tracker'!H5:H1004,"Year 1")/COUNTIFS('📊 Outcome Tracker'!H5:H1004,"Year 1",'📊 Outcome Tracker'!A5:A1004,"<>"""),0) -> 0 | O9: =IFERROR(COUNTIFS('📊 Outcome Tracker'!H5:H1004,"Yes",'📊 Outcome Tracker'!H5:H1004,"Year 2")/COUNTIFS('📊 Outcome Tracker'!H5:H1004,"Year 2",'📊 Outcome Tracker'!A5:A1004,"<>"""),0) -> 0 | P9: =IFERROR(COUNTIFS('📊 Outcome Tracker'!H5:H1004,"Yes",'📊 Outcome Tracker'!H5:H1004,"Year 3")/COUNTIFS('📊 Outcome Tracker'!H5:H1004,"Year 3",'📊 Outcome Tracker'!A5:A1004,"<>"""),0) -> 0 | Q9: =IFERROR(COUNTIFS('📊 Outcome Tracker'!H5:H1004,"Yes",'📊 Outcome Tracker'!H5:H1004,"Year 4")/COUNTIFS('📊 Outcome Tracker'!H5:H1004,"Year 4",'📊 Outcome Tracker'!A5:A1004,"<>"""),0) -> 0 | R9: =IFERROR(COUNTIFS('📊 Outcome Tracker'!H5:H1004,"Yes",'📊 Outcome Tracker'!H5:H1004,"Year 5")/COUNTIFS('📊 Outcome Tracker'!H5:H1004,"Year 5",'📊 Outcome Tracker'!A5:A1004,"<>"""),0) -> 0 | S9: 85%
M10: O5 – Community-led initiatives | N10: =IFERROR(COUNTIFS('📊 Outcome Tracker'!I5:I1004,"Yes",'📊 Outcome Tracker'!H5:H1004,"Year 1")/COUNTIFS('📊 Outcome Tracker'!H5:H1004,"Year 1",'📊 Outcome Tracker'!A5:A1004,"<>"""),0) -> 0 | O10: =IFERROR(COUNTIFS('📊 Outcome Tracker'!I5:I1004,"Yes",'📊 Outcome Tracker'!H5:H1004,"Year 2")/COUNTIFS('📊 Outcome Tracker'!H5:H1004,"Year 2",'📊 Outcome Tracker'!A5:A1004,"<>"""),0) -> 0 | P10: =IFERROR(COUNTIFS('📊 Outcome Tracker'!I5:I1004,"Yes",'📊 Outcome Tracker'!H5:H1004,"Year 3")/COUNTIFS('📊 Outcome Tracker'!H5:H1004,"Year 3",'📊 Outcome Tracker'!A5:A1004,"<>"""),0) -> 0 | Q10: =IFERROR(COUNTIFS('📊 Outcome Tracker'!I5:I1004,"Yes",'📊 Outcome Tracker'!H5:H1004,"Year 4")/COUNTIFS('📊 Outcome Tracker'!H5:H1004,"Year 4",'📊 Outcome Tracker'!A5:A1004,"<>"""),0) -> 0 | R10: =IFERROR(COUNTIFS('📊 Outcome Tracker'!I5:I1004,"Yes",'📊 Outcome Tracker'!H5:H1004,"Year 5")/COUNTIFS('📊 Outcome Tracker'!H5:H1004,"Year 5",'📊 Outcome Tracker'!A5:A1004,"<>"""),0) -> 0 | S10: 10
A27: TABLE 3 — Clients by Borough Per Year | M27: TABLE 4 — Risk Levels & Reporting to Police
A28: Year | B28: Ealing | C28: Hillingdon | D28: Hounslow | E28: Total | M28: Year | N28: High Risk | O28: Medium | P28: Low | Q28: Reported to Police | R28: Not Reported
A29: Year 1 | B29: =COUNTIFS('📋 Client Intake'!G5:G1004,"Ealing",'📋 Client Intake'!AB5:AB1004,"Year 1") -> 2 | C29: =COUNTIFS('📋 Client Intake'!G5:G1004,"Hillingdon",'📋 Client Intake'!AB5:AB1004,"Year 1") -> 1 | D29: =COUNTIFS('📋 Client Intake'!G5:G1004,"Hounslow",'📋 Client Intake'!AB5:AB1004,"Year 1") -> 1 | E29: =B29+C29+D29 -> 4 | M29: Year 1 | N29: =COUNTIFS('📋 Client Intake'!M5:M1004,"High",'📋 Client Intake'!AB5:AB1004,"Year 1") -> 2 | O29: =COUNTIFS('📋 Client Intake'!M5:M1004,"Medium",'📋 Client Intake'!AB5:AB1004,"Year 1") -> 1 | P29: =COUNTIFS('📋 Client Intake'!M5:M1004,"Low",'📋 Client Intake'!AB5:AB1004,"Year 1") -> 1 | Q29: =COUNTIFS('📋 Client Intake'!W5:W1004,"Yes",'📋 Client Intake'!AB5:AB1004,"Year 1") -> 1 | R29: =COUNTIFS('📋 Client Intake'!W5:W1004,"No",'📋 Client Intake'!AB5:AB1004,"Year 1") -> 1
A30: Year 2 | B30: =COUNTIFS('📋 Client Intake'!G5:G1004,"Ealing",'📋 Client Intake'!AB5:AB1004,"Year 2") -> 1 | C30: =COUNTIFS('📋 Client Intake'!G5:G1004,"Hillingdon",'📋 Client Intake'!AB5:AB1004,"Year 2") -> 1 | D30: =COUNTIFS('📋 Client Intake'!G5:G1004,"Hounslow",'📋 Client Intake'!AB5:AB1004,"Year 2") -> 0 | E30: =B30+C30+D30 -> 2 | M30: Year 2 | N30: =COUNTIFS('📋 Client Intake'!M5:M1004,"High",'📋 Client Intake'!AB5:AB1004,"Year 2") -> 1 | O30: =COUNTIFS('📋 Client Intake'!M5:M1004,"Medium",'📋 Client Intake'!AB5:AB1004,"Year 2") -> 1 | P30: =COUNTIFS('📋 Client Intake'!M5:M1004,"Low",'📋 Client Intake'!AB5:AB1004,"Year 2") -> 0 | Q30: =COUNTIFS('📋 Client Intake'!W5:W1004,"Yes",'📋 Client Intake'!AB5:AB1004,"Year 2") -> 0 | R30: =COUNTIFS('📋 Client Intake'!W5:W1004,"No",'📋 Client Intake'!AB5:AB1004,"Year 2") -> 1
A31: Year 3 | B31: =COUNTIFS('📋 Client Intake'!G5:G1004,"Ealing",'📋 Client Intake'!AB5:AB1004,"Year 3") -> 0 | C31: =COUNTIFS('📋 Client Intake'!G5:G1004,"Hillingdon",'📋 Client Intake'!AB5:AB1004,"Year 3") -> 0 | D31: =COUNTIFS('📋 Client Intake'!G5:G1004,"Hounslow",'📋 Client Intake'!AB5:AB1004,"Year 3") -> 0 | E31: =B31+C31+D31 -> 0 | M31: Year 3 | N31: =COUNTIFS('📋 Client Intake'!M5:M1004,"High",'📋 Client Intake'!AB5:AB1004,"Year 3") -> 0 | O31: =COUNTIFS('📋 Client Intake'!M5:M1004,"Medium",'📋 Client Intake'!AB5:AB1004,"Year 3") -> 0 | P31: =COUNTIFS('📋 Client Intake'!M5:M1004,"Low",'📋 Client Intake'!AB5:AB1004,"Year 3") -> 0 | Q31: =COUNTIFS('📋 Client Intake'!W5:W1004,"Yes",'📋 Client Intake'!AB5:AB1004,"Year 3") -> 0 | R31: =COUNTIFS('📋 Client Intake'!W5:W1004,"No",'📋 Client Intake'!AB5:AB1004,"Year 3") -> 0
A32: Year 4 | B32: =COUNTIFS('📋 Client Intake'!G5:G1004,"Ealing",'📋 Client Intake'!AB5:AB1004,"Year 4") -> 0 | C32: =COUNTIFS('📋 Client Intake'!G5:G1004,"Hillingdon",'📋 Client Intake'!AB5:AB1004,"Year 4") -> 0 | D32: =COUNTIFS('📋 Client Intake'!G5:G1004,"Hounslow",'📋 Client Intake'!AB5:AB1004,"Year 4") -> 0 | E32: =B32+C32+D32 -> 0 | M32: Year 4 | N32: =COUNTIFS('📋 Client Intake'!M5:M1004,"High",'📋 Client Intake'!AB5:AB1004,"Year 4") -> 0 | O32: =COUNTIFS('📋 Client Intake'!M5:M1004,"Medium",'📋 Client Intake'!AB5:AB1004,"Year 4") -> 0 | P32: =COUNTIFS('📋 Client Intake'!M5:M1004,"Low",'📋 Client Intake'!AB5:AB1004,"Year 4") -> 0 | Q32: =COUNTIFS('📋 Client Intake'!W5:W1004,"Yes",'📋 Client Intake'!AB5:AB1004,"Year 4") -> 0 | R32: =COUNTIFS('📋 Client Intake'!W5:W1004,"No",'📋 Client Intake'!AB5:AB1004,"Year 4") -> 0
A33: Year 5 | B33: =COUNTIFS('📋 Client Intake'!G5:G1004,"Ealing",'📋 Client Intake'!AB5:AB1004,"Year 5") -> 0 | C33: =COUNTIFS('📋 Client Intake'!G5:G1004,"Hillingdon",'📋 Client Intake'!AB5:AB1004,"Year 5") -> 0 | D33: =COUNTIFS('📋 Client Intake'!G5:G1004,"Hounslow",'📋 Client Intake'!AB5:AB1004,"Year 5") -> 0 | E33: =B33+C33+D33 -> 0 | M33: Year 5 | N33: =COUNTIFS('📋 Client Intake'!M5:M1004,"High",'📋 Client Intake'!AB5:AB1004,"Year 5") -> 0 | O33: =COUNTIFS('📋 Client Intake'!M5:M1004,"Medium",'📋 Client Intake'!AB5:AB1004,"Year 5") -> 0 | P33: =COUNTIFS('📋 Client Intake'!M5:M1004,"Low",'📋 Client Intake'!AB5:AB1004,"Year 5") -> 0 | Q33: =COUNTIFS('📋 Client Intake'!W5:W1004,"Yes",'📋 Client Intake'!AB5:AB1004,"Year 5") -> 0 | R33: =COUNTIFS('📋 Client Intake'!W5:W1004,"No",'📋 Client Intake'!AB5:AB1004,"Year 5") -> 0

Sheet 📝 Quarterly Report
A1: HATE CRIME SUPPORT PROJECT | WEST LONDON EQUALITY CENTRE
A2: ="QUARTERLY MONITORING REPORT | "&'⚙ Settings'!C22&" | City Bridge Foundation" -> QUARTERLY MONITORING REPORT | Q1 2025-26 | City Bridge Foundation
A3: ="Reporting Period: "&TEXT('⚙ Settings'!C20,"DD MMM YYYY")&" to "&TEXT('⚙ Settings'!C21,"DD MMM YYYY")&" | Nov 2025 – Jan 2030 | £480,801" -> Reporting Period: 01 Apr 2026 to 30 Jun 2026 | Nov 2025 – Jan 2030 | £480,801
A5: 1. CLIENT NUMBERS
A6: New clients this quarter | H6: =COUNTIFS('📋 Client Intake'!E5:E1004,">="&'⚙ Settings'!C20,'📋 Client Intake'!E5:E1004,"<="&'⚙ Settings'!C21) -> 1 | K6: Referrals accepted in the reporting period
A7: Total cumulative clients (project to date) | H7: =COUNTA('📋 Client Intake'!C5:C1004) -> 6 | K7: All clients registered since Feb 2025
A8: Active cases at end of quarter | H8: =COUNTIF('📋 Client Intake'!F5:F1004,"Active") -> 5
A9: Cases closed this quarter | H9: =COUNTIFS('📋 Client Intake'!F5:F1004,"Closed",'📋 Client Intake'!E5:E1004,">="&'⚙ Settings'!C20) -> 0
A10: High risk cases (total) | H10: =COUNTIF('📋 Client Intake'!M5:M1004,"High") -> 3 | K10: Priority cases requiring intensive support
A11: % of annual target met | H11: =IFERROR(COUNTIFS('📋 Client Intake'!AB5:AB1004,'⚙ Settings'!C23)/'⚙ Settings'!C12,0) -> 0 | K11: Based on 100 clients per year target
A13: 2. BOROUGH BREAKDOWN
A14: Clients from Ealing | H14: =COUNTIF('📋 Client Intake'!G5:G1004,"Ealing") -> 3 | K14: =IFERROR(TEXT(COUNTIF('📋 Client Intake'!G5:G1004,"Ealing")/COUNTA('📋 Client Intake'!C5:C1004),"0%")&" of all clients","") -> 50% of all clients
A15: Clients from Hillingdon | H15: =COUNTIF('📋 Client Intake'!G5:G1004,"Hillingdon") -> 2 | K15: =IFERROR(TEXT(COUNTIF('📋 Client Intake'!G5:G1004,"Hillingdon")/COUNTA('📋 Client Intake'!C5:C1004),"0%")&" of all clients","") -> 33% of all clients
A16: Clients from Hounslow | H16: =COUNTIF('📋 Client Intake'!G5:G1004,"Hounslow") -> 1 | K16: =IFERROR(TEXT(COUNTIF('📋 Client Intake'!G5:G1004,"Hounslow")/COUNTA('📋 Client Intake'!C5:C1004),"0%")&" of all clients","") -> 17% of all clients
A18: 3. DEMOGRAPHICS
A19: Clients under 25 | H19: =COUNTIF('📋 Client Intake'!I5:I1004,"Under 25") -> 0 | K19: =IFERROR(TEXT(COUNTIF('📋 Client Intake'!I5:I1004,"Under 25")/COUNTA('📋 Client Intake'!C5:C1004),"0%")&" of all clients","") -> 0% of all clients
A20: Female clients | H20: =COUNTIF('📋 Client Intake'!J5:J1004,"Female") -> 3
A21: LGBTQ+ clients | H21: =COUNTIF('📋 Client Intake'!Y5:Y1004,"LGBTQ+") -> 0
A22: Clients with disability / health condition | H22: =COUNTIFS('📋 Client Intake'!Z5:Z1004,"<>None",'📋 Client Intake'!Z5:Z1004,"<>",'📋 Client Intake'!Z5:Z1004,"<>Prefer not to say") -> 3
A23: Clients whose first language is not English | H23: =COUNTIF('📋 Client Intake'!X5:X1004,"Other")+COUNTIF('📋 Client Intake'!X5:X1004,"Interpreter needed") -> 2
A25: 4. ACTIVITIES THIS QUARTER
A26: Activities / events delivered | H26: =COUNTIFS('📅 Activities'!A18:A1000,">="&'⚙ Settings'!C20,'📅 Activities'!A18:A1000,"<="&'⚙ Settings'!C21) -> 0
A27: Total participants reached | H27: =SUMIFS('📅 Activities'!G18:G1000,'📅 Activities'!A18:A1000,">="&'⚙ Settings'!C20,'📅 Activities'!A18:A1000,"<="&'⚙ Settings'!C21) -> 0
A28: Legal advice clinic sessions | H28: =COUNTIFS('📅 Activities'!C18:C1000,"Legal Advice Clinic",'📅 Activities'!A18:A1000,">="&'⚙ Settings'!C20) -> 0
A29: New self-referrals generated from activities | H29: =SUMIFS('📅 Activities'!H18:H1000,'📅 Activities'!A18:A1000,">="&'⚙ Settings'!C20,'📅 Activities'!A18:A1000,"<="&'⚙ Settings'!C21) -> 0
A31: 5. OUTCOMES THIS QUARTER
A32: O1 – Clients reporting better access to legal support | H32: =COUNTIFS('📊 Outcome Tracker'!E5:E1004,"Yes",'📊 Outcome Tracker'!B5:B1004,">="&'⚙ Settings'!C20,'📊 Outcome Tracker'!B5:B1004,"<="&'⚙ Settings'!C21) -> 1 | K32: Count of 'Yes' at latest assessment in this quarter
A33: O2 – Clients with increased confidence to report | H33: =COUNTIFS('📊 Outcome Tracker'!F5:F1004,"Yes",'📊 Outcome Tracker'!B5:B1004,">="&'⚙ Settings'!C20,'📊 Outcome Tracker'!B5:B1004,"<="&'⚙ Settings'!C21) -> 1 | K33: Count of 'Yes' at latest assessment in this quarter
A34: O3 – Partnership/agency engaged | H34: =COUNTIFS('📊 Outcome Tracker'!G5:G1004,"Yes",'📊 Outcome Tracker'!B5:B1004,">="&'⚙ Settings'!C20,'📊 Outcome Tracker'!B5:B1004,"<="&'⚙ Settings'!C21) -> 0 | K34: Count of 'Yes' at latest assessment in this quarter
A35: O4 – Clients reporting increased HC awareness | H35: =COUNTIFS('📊 Outcome Tracker'!H5:H1004,"Yes",'📊 Outcome Tracker'!B5:B1004,">="&'⚙ Settings'!C20,'📊 Outcome Tracker'!B5:B1004,"<="&'⚙ Settings'!C21) -> 2 | K35: Count of 'Yes' at latest assessment in this quarter
A36: O5 – Community-led solutions initiated | H36: =COUNTIFS('📊 Outcome Tracker'!I5:I1004,"Yes",'📊 Outcome Tracker'!B5:B1004,">="&'⚙ Settings'!C20,'📊 Outcome Tracker'!B5:B1004,"<="&'⚙ Settings'!C21) -> 0 | K36: Count of 'Yes' at latest assessment in this quarter
A38: 6. REFERRALS
A39: Incoming referrals this quarter | H39: =COUNTIFS('🔀 Referral Tracker'!A27:A1000,">="&'⚙ Settings'!C20,'🔀 Referral Tracker'!A27:A1000,"<="&'⚙ Settings'!C21,'🔀 Referral Tracker'!D27:D1000,"INCOMING") -> 0
A40: Outgoing referrals made to partners | H40: =COUNTIFS('🔀 Referral Tracker'!A27:A1000,">="&'⚙ Settings'!C20,'🔀 Referral Tracker'!A27:A1000,"<="&'⚙ Settings'!C21,'🔀 Referral Tracker'!D27:D1000,"OUTGOING") -> 0
A42: 7. VOLUNTEERS & TRAINING
A43: Active volunteers | H43: =COUNTIF('🙋 Volunteer Log'!G12:G211,"Active") -> 4
A44: Volunteer hours this quarter | H44: =SUMIFS('🙋 Volunteer Log'!G222:G600,'🙋 Volunteer Log'!A222:A600,">="&'⚙ Settings'!C20,'🙋 Volunteer Log'!A222:A600,"<="&'⚙ Settings'!C21) -> 0
A45: Training sessions delivered this quarter | H45: =COUNTIFS('🎓 Training Register'!A11:A500,">="&'⚙ Settings'!C20,'🎓 Training Register'!A11:A500,"<="&'⚙ Settings'!C21) -> 1
A46: Participants trained this quarter | H46: =SUMIFS('🎓 Training Register'!H11:H500,'🎓 Training Register'!A11:A500,">="&'⚙ Settings'!C20,'🎓 Training Register'!A11:A500,"<="&'⚙ Settings'!C21) -> 22
A48: NARRATIVE SUMMARY — Replace with your commentary before sending to City Bridge Foundation:
...

Sheet 📖 Case Studies
A1: CASE STUDY GENERATOR | Hate Crime Support Project | WLEC
A2: Enter Client Ref in cell E5 — profile auto-populates from Client Intake & Outcome Tracker. Write narrative in sections below.
A4: AUTO-POPULATED CLIENT PROFILE — Enter Client Ref in yellow cell below
A5: Client Reference (type here) | E5: HC/1
A6: Client Initials | E6: =IFERROR(VLOOKUP(E5,'📋 Client Intake'!A:V,2,0),"—") -> Freda Ritchie 1
A7: Borough | E7: =IFERROR(VLOOKUP(E5,'📋 Client Intake'!A:V,6,0),"—") -> Active
A8: Date Referred | E8: =IFERROR(TEXT(VLOOKUP(E5,'📋 Client Intake'!A:V,4,0),"DD MMM YYYY"),"—") -> Omer Ul-haque
A9: Age Group | E9: =IFERROR(VLOOKUP(E5,'📋 Client Intake'!A:V,8,0),"—") -> Other
A10: Gender | E10: =IFERROR(VLOOKUP(E5,'📋 Client Intake'!A:V,9,0),"—") -> 26-55
A11: Type of Hate Crime | E11: =IFERROR(VLOOKUP(E5,'📋 Client Intake'!A:V,13,0),"—") -> High
A12: Risk Level | E12: =IFERROR(VLOOKUP(E5,'📋 Client Intake'!A:V,12,0),"—") -> Prefer not to say
A13: Caseworker | E13: =IFERROR(VLOOKUP(E5,'📋 Client Intake'!A:V,3,0),"—") -> FR1
A14: Referral Source | E14: =IFERROR(VLOOKUP(E5,'📋 Client Intake'!A:V,7,0),"—") -> Ealing
A15: Presenting Issue | E15: =IFERROR(VLOOKUP(E5,'📋 Client Intake'!A:V,22,0),"—") -> 0
A16: Outcome Score (of 5 — latest) | E16: =IFERROR(INDEX('📊 Outcome Tracker'!P:P,MATCH(2,1/('📊 Outcome Tracker'!A:A=E5),1)),"Not yet assessed") -> Not yet assessed
A18: ✏️ BACKGROUND
A19: Describe the client's situation when they first came to the project. What hate crime or incident were they experiencing? What impact was it having on them? (Initials only — no identifying information.)
A24: ✏️ SUPPORT PROVIDED
A25: What did WLEC do to help? Describe casework, legal advice, advocacy, referrals, safety planning, community engagement or any other support provided.
A30: ✏️ IMPACT / OUTCOMES ACHIEVED
A31: What changed for this client? Reference the outcome score above. How does this case demonstrate progress against the 5 project outcomes? Include direct quotes if available.
A36: ✏️ PARTNERSHIP WORKING
A37: Which agencies or partners were involved? What did multi-agency working achieve that WLEC could not have done alone? Any MoUs, new referral pathways, or community trigger actions?
A41: ✏️ KEY LESSONS / CONTRIBUTION TO SUSTAINABILITY
A42: What does this case demonstrate about the project's approach? Any practice changes, systemic issues identified, or contribution to building community resilience?
A47: CASE STUDY LIBRARY — Log Completed Case Studies
A48: Client Ref | B48: Project Year | C48: HC Type | D48: Borough | E48: Outcome Score | F48: Funder Report Used | G48: Notes

Sheet ⚠ Risk Register
A1: RISK REGISTER | Hate Crime Support Project | WLEC
A2: Risks identified in M&E Framework. Update status and actions as the project progresses.
A4: Risk | B4: Probability | C4: Impact | D4: Mitigation Strategy | E4: Owner | F4: Review Date | G4: Current Status | H4: Latest Action Taken
A5: Low engagement from hate crime victims | B5: Medium | C5: High | D5: Targeted outreach via social media, trusted community leaders, and religious institutions | E5: Outreach Coordinator | F5: Quarterly | G5: Active
A6: Delays in legal case resolutions | B6: High | C6: Medium | D6: Regular case review meetings; develop pro-bono legal partnerships | E6: Casework Team Lead | F6: Monthly | G6: Active
A7: Lack of police cooperation in hate crime reporting | B7: Medium | C7: High | D7: Establish formal MoU with police; advocacy for better reporting mechanisms | E7: Project Manager | F7: Bi-annual | G7: Active
A8: Volunteer retention issues | B8: Medium | C8: Medium | D8: Provide regular training, peer mentorship, and formal recognition programmes | E8: Volunteer Coordinator | F8: Quarterly | G8: Active
A9: Insufficient community trust in reporting | B9: Medium | C9: High | D9: Community-led outreach, trusted intermediaries, translated materials | E9: Project Manager | F9: Quarterly | G9: Active
A10: Funder reporting requirements change | B10: Low | C10: Medium | D10: Maintain flexible M&E framework; regular funder communication | E10: Project Director | F10: Bi-annual | G10: Monitor
A11: Key staff turnover | B11: Low | C11: High | D11: Succession planning; full handover documentation; cross-training | E11: Project Director | F11: Annual | G11: Monitor
A12: Digital exclusion preventing online access | B12: Medium | C12: Medium | D12: Maintain in-person and telephone support options alongside digital | E12: Casework Team | F12: Ongoing | G12: Active

Sheet ⚙ Settings
A1: PROJECT SETTINGS & CONFIGURATION
A2: SharePoint version history tracks who made changes and when — access via File > Version History in SharePoint/OneDrive.
A4: Project Name | C4: Hate Crime Support Project
A5: Lead Organisation | C5: West London Equality Centre (WLEC)
A6: Funder | C6: City Bridge Foundation
A7: Total Funding | C7: £480,801
A8: Project Start Date | C8: 01/11/2025
A9: Project End Date | C9: 31/10/2030
A10: Project Duration | C10: 5 Years (Nov 2025 – Oct 2030)
A11: Current Project Year | C11: Year 1 (2025-26)
A12: Annual Client Target | C12: 50
A13: 5-Year Client Target | C13: 250
A14: Boroughs Covered | C14: Ealing, Hillingdon, Hounslow
A15: Contact Email | C15: freda@hrsg.org.uk
A16: Report Prepared By
A17: Date of Last Update
A19: QUARTERLY REPORT CONFIGURATION — Update each quarter
A20: Quarter Start Date | C20: 46113 | D20: Change to current quarter start
A21: Quarter End Date | C21: 30/06/2026 | D21: Change to current quarter end
A22: Quarter Label | C22: Q1 2025-26 | D22: e.g. Q1 2025-26
A23: Current Year Label | C23: Year 1 (2025-26) | D23: Update each project year
A24: Year Number (1-5) | C24: 1 | D24: Used in trend charts
A28: 5-YEAR ACTIVITY TARGETS (from framework)
